Not Found: /favicon.ico
Internal Server Error: /order_webhook/
Traceback (most recent call last):
  File "/Users/nakulpathak/Documents/Projects/shopify-app/lib/python2.7/site-packages/django/core/handlers/base.py", line 111, in get_response
    response = wrapped_callback(request, *callback_args, **callback_kwargs)
  File "/Users/nakulpathak/Documents/Projects/shopify-app/lib/python2.7/site-packages/django/views/decorators/csrf.py", line 57, in wrapped_view
    return view_func(*args, **kwargs)
  File "/Users/nakulpathak/Documents/Projects/shopify-app/shopify_app/views.py", line 50, in webhook
    user = user_model.objects.get(domain = request.META['HTTP_X_SHOPIFY_SHOP_DOMAIN'])
  File "/Users/nakulpathak/Documents/Projects/shopify-app/lib/python2.7/site-packages/django/db/models/manager.py", line 92, in manager_method
    return getattr(self.get_queryset(), name)(*args, **kwargs)
  File "/Users/nakulpathak/Documents/Projects/shopify-app/lib/python2.7/site-packages/django/db/models/query.py", line 345, in get
    clone = self.filter(*args, **kwargs)
  File "/Users/nakulpathak/Documents/Projects/shopify-app/lib/python2.7/site-packages/django/db/models/query.py", line 691, in filter
    return self._filter_or_exclude(False, *args, **kwargs)
  File "/Users/nakulpathak/Documents/Projects/shopify-app/lib/python2.7/site-packages/django/db/models/query.py", line 709, in _filter_or_exclude
    clone.query.add_q(Q(*args, **kwargs))
  File "/Users/nakulpathak/Documents/Projects/shopify-app/lib/python2.7/site-packages/django/db/models/sql/query.py", line 1331, in add_q
    clause, require_inner = self._add_q(where_part, self.used_aliases)
  File "/Users/nakulpathak/Documents/Projects/shopify-app/lib/python2.7/site-packages/django/db/models/sql/query.py", line 1358, in _add_q
    current_negated=current_negated, connector=connector)
  File "/Users/nakulpathak/Documents/Projects/shopify-app/lib/python2.7/site-packages/django/db/models/sql/query.py", line 1182, in build_filter
    lookups, parts, reffed_aggregate = self.solve_lookup_type(arg)
  File "/Users/nakulpathak/Documents/Projects/shopify-app/lib/python2.7/site-packages/django/db/models/sql/query.py", line 1120, in solve_lookup_type
    _, field, _, lookup_parts = self.names_to_path(lookup_splitted, self.get_meta())
  File "/Users/nakulpathak/Documents/Projects/shopify-app/lib/python2.7/site-packages/django/db/models/sql/query.py", line 1427, in names_to_path
    self.raise_field_error(opts, name)
  File "/Users/nakulpathak/Documents/Projects/shopify-app/lib/python2.7/site-packages/django/db/models/sql/query.py", line 1433, in raise_field_error
    "Choices are: %s" % (name, ", ".join(available)))
FieldError: Cannot resolve keyword 'domain' into field. Choices are: id, last_login, logentry, myshopify_domain, password, token
Internal Server Error: /order_webhook/
Traceback (most recent call last):
  File "/Users/nakulpathak/Documents/Projects/shopify-app/lib/python2.7/site-packages/django/core/handlers/base.py", line 111, in get_response
    response = wrapped_callback(request, *callback_args, **callback_kwargs)
  File "/Users/nakulpathak/Documents/Projects/shopify-app/lib/python2.7/site-packages/django/views/decorators/csrf.py", line 57, in wrapped_view
    return view_func(*args, **kwargs)
  File "/Users/nakulpathak/Documents/Projects/shopify-app/shopify_app/views.py", line 50, in webhook
    user = user_model.objects.get(domain = request.META['HTTP_X_SHOPIFY_SHOP_DOMAIN'])
  File "/Users/nakulpathak/Documents/Projects/shopify-app/lib/python2.7/site-packages/django/db/models/manager.py", line 92, in manager_method
    return getattr(self.get_queryset(), name)(*args, **kwargs)
  File "/Users/nakulpathak/Documents/Projects/shopify-app/lib/python2.7/site-packages/django/db/models/query.py", line 345, in get
    clone = self.filter(*args, **kwargs)
  File "/Users/nakulpathak/Documents/Projects/shopify-app/lib/python2.7/site-packages/django/db/models/query.py", line 691, in filter
    return self._filter_or_exclude(False, *args, **kwargs)
  File "/Users/nakulpathak/Documents/Projects/shopify-app/lib/python2.7/site-packages/django/db/models/query.py", line 709, in _filter_or_exclude
    clone.query.add_q(Q(*args, **kwargs))
  File "/Users/nakulpathak/Documents/Projects/shopify-app/lib/python2.7/site-packages/django/db/models/sql/query.py", line 1331, in add_q
    clause, require_inner = self._add_q(where_part, self.used_aliases)
  File "/Users/nakulpathak/Documents/Projects/shopify-app/lib/python2.7/site-packages/django/db/models/sql/query.py", line 1358, in _add_q
    current_negated=current_negated, connector=connector)
  File "/Users/nakulpathak/Documents/Projects/shopify-app/lib/python2.7/site-packages/django/db/models/sql/query.py", line 1182, in build_filter
    lookups, parts, reffed_aggregate = self.solve_lookup_type(arg)
  File "/Users/nakulpathak/Documents/Projects/shopify-app/lib/python2.7/site-packages/django/db/models/sql/query.py", line 1120, in solve_lookup_type
    _, field, _, lookup_parts = self.names_to_path(lookup_splitted, self.get_meta())
  File "/Users/nakulpathak/Documents/Projects/shopify-app/lib/python2.7/site-packages/django/db/models/sql/query.py", line 1427, in names_to_path
    self.raise_field_error(opts, name)
  File "/Users/nakulpathak/Documents/Projects/shopify-app/lib/python2.7/site-packages/django/db/models/sql/query.py", line 1433, in raise_field_error
    "Choices are: %s" % (name, ", ".join(available)))
FieldError: Cannot resolve keyword 'domain' into field. Choices are: id, last_login, logentry, myshopify_domain, password, token
